<mujoco model="b1">
  <compiler angle="radian" autolimits="true" meshdir="meshes" />
  <statistic meansize="0.278245" extent="1.36353" center="4.68679e-05 0.000420435 -0.142055" />
  <asset>
    <material name="dark" specular="0" shininess="0.25" rgba="0.2 0.2 0.2 1" />

    <mesh name="trunk" file="trunk.stl" />
    <mesh name="hip" file="hip.stl" />
    <mesh name="thigh_mirror" file="thigh_mirror.stl" />
    <mesh name="calf" file="calf.stl" />
    <mesh name="thigh" file="thigh.stl" />
  </asset>

  <option cone="elliptic" impratio="100" />

  <default>
    <default class="b1">
      <geom friction="0.6" margin="0.001" />
      <joint damping="2" armature="0.01" frictionloss="0.2" />
      <!-- TODO: ctrlrange defines torques limits that we can put on each motor, probably it does
      not correlate with unitree B1 docs -->
      <motor ctrlrange="-20 20" />
      <default class="hip_joint">
        <joint range="-0.75 0.75" axis="1 0 0" pos="0 0 0" />
      </default>
      <default class="thigh_joint">
        <joint range="-1 3.5" axis="0 1 0" pos="0 0 0" />
      </default>
      <default class="calf_joint">
        <joint pos="0 0 0" axis="0 1 0" range="-2.6 -0.6" />
      </default>
      <default class="visual">
        <geom type="mesh" contype="0" conaffinity="0" group="2" material="dark" />
      </default>
      <default class="collision">
        <geom group="3" type="capsule" />
        <default class="hip_right1">
          <geom size="0.09 0.02" pos="0 -0.12675 0" quat="0.707107 0.707107 0 0" type="cylinder" />
        </default>
        <default class="hip_right2">
          <geom size="0.05 0.01" pos="0 -0.00935 0" quat="0.707107 0.707107 0 0" type="cylinder" />
        </default>
        <default class="hip_left1">
          <geom size="0.09 0.02" pos="0 0.12675 0" quat="0.707107 0.707107 0 0" type="cylinder" />
        </default>
        <default class="hip_left2">
          <geom size="0.05 0.01" pos="0 0.00935 0" quat="0.707107 0.707107 0 0" type="cylinder" />
        </default>
        <default class="thigh_right1">
          <geom size="0.175 0.025 0.04" pos="0 0 -0.175" quat="0.707107 0 0.707107 0" type="box" />
        </default>
        <default class="thigh_right2">
          <geom size="0.05 0.01" pos="0 0.0519 0" quat="0.707107 0.707107 0 0" type="cylinder" />
        </default>
        <default class="thigh_left1">
          <geom size="0.175 0.025 0.04" pos="0 0 -0.175" quat="0.707107 0 0.707107 0" type="box" />
        </default>
        <default class="thigh_left2">
          <geom size="0.05 0.01" pos="0 -0.0519 0" quat="0.707107 0.707107 0 0" type="cylinder" />
        </default>
        <default class="calf1">
          <geom size="0.175 0.02 0.025" pos="0 0 -0.175" quat="0.707107 0 0.707107 0" type="box" />
        </default>
        <default class="calf2">
          <geom size="0.01" fromto="0.02 0 -0.13 0 0 -0.2" />
        </default>
        <default class="foot">
          <geom type="sphere" size="0.02" pos="0 0 -0.2" priority="1" solimp="0.015 1 0.031"
            condim="6"
            friction="0.8 0.02 0.01" />
        </default>
      </default>
    </default>
  </default>

  <worldbody>
    <body name="trunk" pos="0 0 0.74">
      <!-- <freejoint /> -->
      <joint name="world_joint_TX" pos="0 0 0" axis="1 0 0" type="slide"/>
      <joint name="world_joint_TY" pos="0 0 0" axis="0 0 -1" type="slide"/>
      <joint name="world_joint_RZ" pos="0 0 0" axis="0 1 0"/>
      <geom class="visual" mesh="trunk" />
      <geom class="collision" size="0.2535 0.15 0.075" type="box" />
      <geom class="collision" size="0.05 0.01" pos="0.1955 -0.072 0" quat="0.707107 0 0.707107 0"
        type="cylinder" />
      <geom class="collision" size="0.05 0.01" pos="0.1955 0.072 0" quat="0.707107 0 0.707107 0"
        type="cylinder" />
      <geom class="collision" size="0.05 0.01" pos="-0.1955 -0.072 0" quat="0.707107 0 0.707107 0"
        type="cylinder" />
      <geom class="collision" size="0.05 0.01" pos="-0.1955 0.072 0" quat="0.707107 0 0.707107 0"
        type="cylinder" />
      <body name="FR_hip" pos="0.3455 -0.072 0">
        <inertial pos="-0.018016 -0.00971213 9.67456e-05" quat="0.514022 0.512801 0.485949 0.486488"
          mass="2.366" diaginertia="0.00980696 0.00664332 0.0045362" />
        <!-- <joint class="hip_joint"
          name="FR_hip_joint" /> -->
        <geom class="visual" mesh="hip" />
        <geom class="hip_right1" />
        <geom class="hip_right2" />
        <body name="FR_thigh"
          pos="0 -0.12675 0">
          <inertial pos="-0.000220117 0.0301731 -0.0507383"
            quat="0.736596 -0.0378368 0.076521 0.670924" mass="4.2"
            diaginertia="0.0487177 0.0459334 0.00814802" />
          <joint class="thigh_joint" name="FR_thigh_joint" />
          <geom class="visual" mesh="thigh_mirror" />
          <geom class="thigh_right1" />
          <geom class="thigh_right2" />
          <body name="FR_calf" pos="0 0 -0.35">
            <inertial pos="0.0049483 0 -0.210919" quat="0.707231 -0.00481122 -0.00483372 0.70695"
              mass="0.907" diaginertia="0.0162164 0.0160695 0.000406131" />
            <joint class="calf_joint" name="FR_calf_joint" />
            <geom class="visual" mesh="calf" />
            <geom class="calf1" />
            <geom class="calf2" />
            <geom class="foot" />
          </body>
        </body>
      </body>
      <body name="FL_hip" pos="0.3455 0.072 0">
        <inertial pos="-0.018016 0.00971213 9.67456e-05" quat="0.486488 0.485949 0.512801 0.514022"
          mass="2.366" diaginertia="0.00980696 0.00664332 0.0045362" />
        <!-- <joint class="hip_joint" name="FL_hip_joint" /> -->
        <geom class="visual" mesh="hip" />
        <geom class="hip_left1" />
        <geom class="hip_left2" />
        <body name="FL_thigh" pos="0 0.12675 0">
          <inertial pos="-0.000220117 -0.0301731 -0.0507383"
            quat="0.670924 0.076521 -0.0378368 0.736596" mass="4.2"
            diaginertia="0.0487177 0.0459334 0.00814802" />
          <joint class="thigh_joint" name="FL_thigh_joint" />
          <geom class="visual" mesh="thigh" />
          <geom class="thigh_left1" />
          <geom class="thigh_left2" />
          <body name="FL_calf" pos="0 0 -0.35">
            <inertial pos="0.0049483 0 -0.210919" quat="0.707231 -0.00481122 -0.00483372 0.70695"
              mass="0.907" diaginertia="0.0162164 0.0160695 0.000406131" />
            <joint class="calf_joint" name="FL_calf_joint" />
            <geom class="visual" mesh="calf" />
            <geom class="calf1" />
            <geom class="calf2" />
            <geom class="foot" />
          </body>
        </body>
      </body>
      <body name="RR_hip" pos="-0.3455 -0.072 0">
        <inertial pos="0.018016 -0.00971213 9.67456e-05" quat="0.485949 0.486488 0.514022 0.512801"
          mass="2.366" diaginertia="0.00980696 0.00664332 0.0045362" />
        <!-- <joint class="hip_joint" name="RR_hip_joint" /> -->
        <geom class="visual" mesh="hip" />
        <geom class="hip_right1" />
        <geom class="hip_right2" />
        <body name="RR_thigh" pos="0 -0.12675 0">
          <inertial pos="-0.000220117 0.0301731 -0.0507383"
            quat="0.736596 -0.0378368 0.076521 0.670924" mass="4.2"
            diaginertia="0.0487177 0.0459334 0.00814802" />
          <joint class="thigh_joint" name="RR_thigh_joint" />
          <geom class="visual" mesh="thigh_mirror" />
          <geom class="thigh_right1" />
          <geom class="thigh_right2" />
          <body name="RR_calf" pos="0 0 -0.35">
            <inertial pos="0.0049483 0 -0.210919" quat="0.707231 -0.00481122 -0.00483372 0.70695"
              mass="0.907" diaginertia="0.0162164 0.0160695 0.000406131" />
            <joint class="calf_joint" name="RR_calf_joint" />
            <geom class="visual" mesh="calf" />
            <geom class="calf1" />
            <geom class="calf2" />
            <geom class="foot" />
          </body>
        </body>
      </body>
      <body name="RL_hip" pos="-0.3455 0.072 0">
        <inertial pos="0.018016 0.00971213 9.67456e-05" quat="0.512801 0.514022 0.486488 0.485949"
          mass="2.366" diaginertia="0.00980696 0.00664332 0.0045362" />
        <!-- <joint class="hip_joint" name="RL_hip_joint" /> -->
        <geom class="visual" mesh="hip" />
        <geom class="hip_left1" />
        <geom class="hip_left2" />
        <body name="RL_thigh" pos="0 0.12675 0">
          <inertial pos="-0.000220117 -0.0301731 -0.0507383"
            quat="0.670924 0.076521 -0.0378368 0.736596" mass="4.2"
            diaginertia="0.0487177 0.0459334 0.00814802" />
          <joint class="thigh_joint" name="RL_thigh_joint" />
          <geom class="visual" mesh="thigh" />
          <geom class="thigh_left1" />
          <geom class="thigh_left2" />
          <body name="RL_calf" pos="0 0 -0.35">
            <inertial pos="0.0049483 0 -0.210919" quat="0.707231 -0.00481122 -0.00483372 0.70695"
              mass="0.907" diaginertia="0.0162164 0.0160695 0.000406131" />
            <joint class="calf_joint" name="RL_calf_joint" />
            <geom class="visual" mesh="calf" />
            <geom class="calf1" />
            <geom class="calf2" />
            <geom class="foot" />
          </body>
        </body>
      </body>
    </body>
  </worldbody>

  <actuator>
    <!-- <motor class="hip_joint" name="FR_hip_motor" joint="FR_hip_joint" /> -->
    <motor class="thigh_joint" name="FR_thigh_motor" joint="FR_thigh_joint" />
    <motor class="calf_joint" name="FR_calf_motor" joint="FR_calf_joint" />
    <!-- <motor class="hip_joint" name="FL_hip_motor" joint="FL_hip_joint" /> -->
    <motor class="thigh_joint" name="FL_thigh_motor" joint="FL_thigh_joint" />
    <motor class="calf_joint" name="FL_calf_motor" joint="FL_calf_joint" />
    <!-- <motor class="hip_joint" name="RR_hip_motor" joint="RR_hip_joint" /> -->
    <motor class="thigh_joint" name="RR_thigh_motor" joint="RR_thigh_joint" />
    <motor class="calf_joint" name="RR_calf_motor" joint="RR_calf_joint" />
    <!-- <motor class="hip_joint" name="RL_hip_motor" joint="RL_hip_joint" /> -->
    <motor class="thigh_joint" name="RL_thigh_motor" joint="RL_thigh_joint" />
    <motor class="calf_joint" name="RL_calf_motor" joint="RL_calf_joint" />
  </actuator>
</mujoco>